2024-04-20 08:15:50,938 INFO    StreamThr :29339 [internal.py:wandb_internal():86] W&B internal server running at pid: 29339, started at: 2024-04-20 08:15:50.937135
2024-04-20 08:15:50,942 DEBUG   HandlerThread:29339 [handler.py:handle_request():146] handle_request: status
2024-04-20 08:15:50,950 INFO    WriterThread:29339 [datastore.py:open_for_write():87] open: /logfiles/facebook-opt-125m_rte-64_0_0_2024-04-20-08-15-18/wandb/wandb/run-20240420_081550-radlv76p/run-radlv76p.wandb
2024-04-20 08:15:50,951 DEBUG   SenderThread:29339 [sender.py:send():379] send: header
2024-04-20 08:15:51,002 DEBUG   SenderThread:29339 [sender.py:send():379] send: run
2024-04-20 08:15:51,489 ERROR   SenderThread:29339 [internal_api.py:execute():373] 400 response executing GraphQL.
2024-04-20 08:15:51,489 ERROR   SenderThread:29339 [internal_api.py:execute():374] {"errors":[{"message":"you may not log runs directly to your organization, please try using your team entity","path":["upsertBucket"]}],"data":{"upsertBucket":null}}
2024-04-20 08:15:51,490 ERROR   SenderThread:29339 [sender.py:send_run():971] you may not log runs directly to your organization, please try using your team entity (Error 400: Bad Request)
Traceback (most recent call last):
  File "/opt/conda/lib/python3.8/site-packages/wandb/apis/normalize.py", line 41, in wrapper
    return func(*args, **kwargs)
  File "/opt/conda/lib/python3.8/site-packages/wandb/sdk/internal/internal_api.py", line 2217, in upsert_run
    response = self.gql(
  File "/opt/conda/lib/python3.8/site-packages/wandb/sdk/internal/internal_api.py", line 341, in gql
    ret = self._retry_gql(
  File "/opt/conda/lib/python3.8/site-packages/wandb/sdk/lib/retry.py", line 131, in __call__
    result = self._call_fn(*args, **kwargs)
  File "/opt/conda/lib/python3.8/site-packages/wandb/sdk/internal/internal_api.py", line 369, in execute
    return self.client.execute(*args, **kwargs)  # type: ignore
  File "/opt/conda/lib/python3.8/site-packages/wandb/vendor/gql-0.2.0/wandb_gql/client.py", line 52, in execute
    result = self._get_result(document, *args, **kwargs)
  File "/opt/conda/lib/python3.8/site-packages/wandb/vendor/gql-0.2.0/wandb_gql/client.py", line 60, in _get_result
    return self.transport.execute(document, *args, **kwargs)
  File "/opt/conda/lib/python3.8/site-packages/wandb/sdk/lib/gql_request.py", line 59, in execute
    request.raise_for_status()
  File "/opt/conda/lib/python3.8/site-packages/requests/models.py", line 1021, in raise_for_status
    raise HTTPError(http_error_msg, response=self)
requests.exceptions.HTTPError: 400 Client Error: Bad Request for url: https://api.wandb.ai/graphql

During handling of the above exception, another exception occurred:

Traceback (most recent call last):
  File "/opt/conda/lib/python3.8/site-packages/wandb/sdk/internal/sender.py", line 969, in send_run
    server_run = self._init_run(run, config_value_dict)
  File "/opt/conda/lib/python3.8/site-packages/wandb/sdk/internal/sender.py", line 1014, in _init_run
    server_run, inserted, server_messages = self._api.upsert_run(
  File "/opt/conda/lib/python3.8/site-packages/wandb/apis/normalize.py", line 51, in wrapper
    raise CommError(message, error)
wandb.errors.CommError: you may not log runs directly to your organization, please try using your team entity (Error 400: Bad Request)
2024-04-20 08:15:51,610 DEBUG   HandlerThread:29339 [handler.py:handle_request():146] handle_request: shutdown
2024-04-20 08:15:51,610 INFO    HandlerThread:29339 [handler.py:finish():866] shutting down handler
2024-04-20 08:15:52,002 INFO    WriterThread:29339 [datastore.py:close():296] close: /logfiles/facebook-opt-125m_rte-64_0_0_2024-04-20-08-15-18/wandb/wandb/run-20240420_081550-radlv76p/run-radlv76p.wandb
2024-04-20 08:15:52,499 INFO    SenderThread:29339 [sender.py:finish():1546] shutting down sender
